{
 "cells": [
  {
   "cell_type": "code",
   "execution_count": 3,
   "metadata": {},
   "outputs": [],
   "source": [
    "import os"
   ]
  },
  {
   "cell_type": "code",
   "execution_count": 1,
   "metadata": {},
   "outputs": [
    {
     "data": {
      "text/plain": [
       "'/workspaces/churn_data1/research'"
      ]
     },
     "execution_count": 1,
     "metadata": {},
     "output_type": "execute_result"
    }
   ],
   "source": [
    "%pwd"
   ]
  },
  {
   "cell_type": "code",
   "execution_count": 4,
   "metadata": {},
   "outputs": [],
   "source": [
    "os.chdir(\"../\")"
   ]
  },
  {
   "cell_type": "code",
   "execution_count": 5,
   "metadata": {},
   "outputs": [
    {
     "data": {
      "text/plain": [
       "'/workspaces/churn_data1'"
      ]
     },
     "execution_count": 5,
     "metadata": {},
     "output_type": "execute_result"
    }
   ],
   "source": [
    "%pwd"
   ]
  },
  {
   "cell_type": "code",
   "execution_count": 10,
   "metadata": {},
   "outputs": [],
   "source": [
    "import pandas as pd"
   ]
  },
  {
   "cell_type": "code",
   "execution_count": 11,
   "metadata": {},
   "outputs": [
    {
     "name": "stdout",
     "output_type": "stream",
     "text": [
      "Unexpected exception formatting exception. Falling back to standard exception\n"
     ]
    },
    {
     "name": "stderr",
     "output_type": "stream",
     "text": [
      "Traceback (most recent call last):\n",
      "  File \"/home/codespace/.local/lib/python3.12/site-packages/IPython/core/interactiveshell.py\", line 3577, in run_code\n",
      "    exec(code_obj, self.user_global_ns, self.user_ns)\n",
      "  File \"/tmp/ipykernel_29831/2580800199.py\", line 1, in <module>\n",
      "    data = pd.read_csv(\"artifacts/data_ingestion/Churn_Modelling (1).csv\")\n",
      "           ^^^^^^^^^^^^^^^^^^^^^^^^^^^^^^^^^^^^^^^^^^^^^^^^^^^^^^^^^^^^^^^\n",
      "  File \"/home/codespace/.local/lib/python3.12/site-packages/pandas/io/parsers/readers.py\", line 1026, in read_csv\n",
      "    return _read(filepath_or_buffer, kwds)\n",
      "           ^^^^^^^^^^^^^^^^^^^^^^^^^^^^^^^\n",
      "  File \"/home/codespace/.local/lib/python3.12/site-packages/pandas/io/parsers/readers.py\", line 620, in _read\n",
      "    parser = TextFileReader(filepath_or_buffer, **kwds)\n",
      "             ^^^^^^^^^^^^^^^^^^^^^^^^^^^^^^^^^^^^^^^^^^\n",
      "  File \"/home/codespace/.local/lib/python3.12/site-packages/pandas/io/parsers/readers.py\", line 1620, in __init__\n",
      "    self._engine = self._make_engine(f, self.engine)\n",
      "                   ^^^^^^^^^^^^^^^^^^^^^^^^^^^^^^^^^\n",
      "  File \"/home/codespace/.local/lib/python3.12/site-packages/pandas/io/parsers/readers.py\", line 1880, in _make_engine\n",
      "    self.handles = get_handle(\n",
      "                   ^^^^^^^^^^^\n",
      "  File \"/home/codespace/.local/lib/python3.12/site-packages/pandas/io/common.py\", line 873, in get_handle\n",
      "    handle = open(\n",
      "             ^^^^^\n",
      "FileNotFoundError: [Errno 2] No such file or directory: 'artifacts/data_ingestion/Churn_Modelling (1).csv'\n",
      "\n",
      "During handling of the above exception, another exception occurred:\n",
      "\n",
      "Traceback (most recent call last):\n",
      "  File \"/home/codespace/.local/lib/python3.12/site-packages/IPython/core/interactiveshell.py\", line 2168, in showtraceback\n",
      "    stb = self.InteractiveTB.structured_traceback(\n",
      "          ^^^^^^^^^^^^^^^^^^^^^^^^^^^^^^^^^^^^^^^^\n",
      "  File \"/home/codespace/.local/lib/python3.12/site-packages/IPython/core/ultratb.py\", line 1457, in structured_traceback\n",
      "    return FormattedTB.structured_traceback(\n",
      "           ^^^^^^^^^^^^^^^^^^^^^^^^^^^^^^^^^\n",
      "  File \"/home/codespace/.local/lib/python3.12/site-packages/IPython/core/ultratb.py\", line 1348, in structured_traceback\n",
      "    return VerboseTB.structured_traceback(\n",
      "           ^^^^^^^^^^^^^^^^^^^^^^^^^^^^^^^\n",
      "  File \"/home/codespace/.local/lib/python3.12/site-packages/IPython/core/ultratb.py\", line 1195, in structured_traceback\n",
      "    formatted_exception = self.format_exception_as_a_whole(etype, evalue, etb, number_of_lines_of_context,\n",
      "                          ^^^^^^^^^^^^^^^^^^^^^^^^^^^^^^^^^^^^^^^^^^^^^^^^^^^^^^^^^^^^^^^^^^^^^^^^^^^^^^^^\n",
      "  File \"/home/codespace/.local/lib/python3.12/site-packages/IPython/core/ultratb.py\", line 1110, in format_exception_as_a_whole\n",
      "    frames.append(self.format_record(record))\n",
      "                  ^^^^^^^^^^^^^^^^^^^^^^^^^^\n",
      "  File \"/home/codespace/.local/lib/python3.12/site-packages/IPython/core/ultratb.py\", line 992, in format_record\n",
      "    frame_info.lines, Colors, self.has_colors, lvals\n",
      "    ^^^^^^^^^^^^^^^^\n",
      "  File \"/home/codespace/.local/lib/python3.12/site-packages/IPython/core/ultratb.py\", line 804, in lines\n",
      "    return self._sd.lines\n",
      "           ^^^^^^^^^^^^^^\n",
      "  File \"/home/codespace/.local/lib/python3.12/site-packages/stack_data/utils.py\", line 145, in cached_property_wrapper\n",
      "    value = obj.__dict__[self.func.__name__] = self.func(obj)\n",
      "                                               ^^^^^^^^^^^^^^\n",
      "  File \"/home/codespace/.local/lib/python3.12/site-packages/stack_data/core.py\", line 734, in lines\n",
      "    pieces = self.included_pieces\n",
      "             ^^^^^^^^^^^^^^^^^^^^\n",
      "  File \"/home/codespace/.local/lib/python3.12/site-packages/stack_data/utils.py\", line 145, in cached_property_wrapper\n",
      "    value = obj.__dict__[self.func.__name__] = self.func(obj)\n",
      "                                               ^^^^^^^^^^^^^^\n",
      "  File \"/home/codespace/.local/lib/python3.12/site-packages/stack_data/core.py\", line 677, in included_pieces\n",
      "    scope_pieces = self.scope_pieces\n",
      "                   ^^^^^^^^^^^^^^^^^\n",
      "  File \"/home/codespace/.local/lib/python3.12/site-packages/stack_data/utils.py\", line 145, in cached_property_wrapper\n",
      "    value = obj.__dict__[self.func.__name__] = self.func(obj)\n",
      "                                               ^^^^^^^^^^^^^^\n",
      "  File \"/home/codespace/.local/lib/python3.12/site-packages/stack_data/core.py\", line 614, in scope_pieces\n",
      "    scope_start, scope_end = self.source.line_range(self.scope)\n",
      "                             ^^^^^^^^^^^^^^^^^^^^^^^^^^^^^^^^^^\n",
      "  File \"/home/codespace/.local/lib/python3.12/site-packages/stack_data/core.py\", line 178, in line_range\n",
      "    return line_range(self.asttext(), node)\n",
      "                      ^^^^^^^^^^^^\n",
      "AttributeError: 'Source' object has no attribute 'asttext'\n"
     ]
    }
   ],
   "source": [
    "data = pd.read_csv(\"artifacts/data_ingestion/Churn_Modelling (1).csv\")\n",
    "data.head()"
   ]
  },
  {
   "cell_type": "code",
   "execution_count": 9,
   "metadata": {},
   "outputs": [
    {
     "name": "stdout",
     "output_type": "stream",
     "text": [
      "Unexpected exception formatting exception. Falling back to standard exception\n"
     ]
    },
    {
     "name": "stderr",
     "output_type": "stream",
     "text": [
      "Traceback (most recent call last):\n",
      "  File \"/home/codespace/.local/lib/python3.12/site-packages/IPython/core/interactiveshell.py\", line 3577, in run_code\n",
      "    exec(code_obj, self.user_global_ns, self.user_ns)\n",
      "  File \"/tmp/ipykernel_29831/169168403.py\", line 1, in <module>\n",
      "    data.info()\n",
      "    ^^^^\n",
      "NameError: name 'data' is not defined\n",
      "\n",
      "During handling of the above exception, another exception occurred:\n",
      "\n",
      "Traceback (most recent call last):\n",
      "  File \"/home/codespace/.local/lib/python3.12/site-packages/IPython/core/interactiveshell.py\", line 2168, in showtraceback\n",
      "    stb = self.InteractiveTB.structured_traceback(\n",
      "          ^^^^^^^^^^^^^^^^^^^^^^^^^^^^^^^^^^^^^^^^\n",
      "  File \"/home/codespace/.local/lib/python3.12/site-packages/IPython/core/ultratb.py\", line 1457, in structured_traceback\n",
      "    return FormattedTB.structured_traceback(\n",
      "           ^^^^^^^^^^^^^^^^^^^^^^^^^^^^^^^^^\n",
      "  File \"/home/codespace/.local/lib/python3.12/site-packages/IPython/core/ultratb.py\", line 1348, in structured_traceback\n",
      "    return VerboseTB.structured_traceback(\n",
      "           ^^^^^^^^^^^^^^^^^^^^^^^^^^^^^^^\n",
      "  File \"/home/codespace/.local/lib/python3.12/site-packages/IPython/core/ultratb.py\", line 1195, in structured_traceback\n",
      "    formatted_exception = self.format_exception_as_a_whole(etype, evalue, etb, number_of_lines_of_context,\n",
      "                          ^^^^^^^^^^^^^^^^^^^^^^^^^^^^^^^^^^^^^^^^^^^^^^^^^^^^^^^^^^^^^^^^^^^^^^^^^^^^^^^^\n",
      "  File \"/home/codespace/.local/lib/python3.12/site-packages/IPython/core/ultratb.py\", line 1110, in format_exception_as_a_whole\n",
      "    frames.append(self.format_record(record))\n",
      "                  ^^^^^^^^^^^^^^^^^^^^^^^^^^\n",
      "  File \"/home/codespace/.local/lib/python3.12/site-packages/IPython/core/ultratb.py\", line 992, in format_record\n",
      "    frame_info.lines, Colors, self.has_colors, lvals\n",
      "    ^^^^^^^^^^^^^^^^\n",
      "  File \"/home/codespace/.local/lib/python3.12/site-packages/IPython/core/ultratb.py\", line 804, in lines\n",
      "    return self._sd.lines\n",
      "           ^^^^^^^^^^^^^^\n",
      "  File \"/home/codespace/.local/lib/python3.12/site-packages/stack_data/utils.py\", line 145, in cached_property_wrapper\n",
      "    value = obj.__dict__[self.func.__name__] = self.func(obj)\n",
      "                                               ^^^^^^^^^^^^^^\n",
      "  File \"/home/codespace/.local/lib/python3.12/site-packages/stack_data/core.py\", line 734, in lines\n",
      "    pieces = self.included_pieces\n",
      "             ^^^^^^^^^^^^^^^^^^^^\n",
      "  File \"/home/codespace/.local/lib/python3.12/site-packages/stack_data/utils.py\", line 145, in cached_property_wrapper\n",
      "    value = obj.__dict__[self.func.__name__] = self.func(obj)\n",
      "                                               ^^^^^^^^^^^^^^\n",
      "  File \"/home/codespace/.local/lib/python3.12/site-packages/stack_data/core.py\", line 677, in included_pieces\n",
      "    scope_pieces = self.scope_pieces\n",
      "                   ^^^^^^^^^^^^^^^^^\n",
      "  File \"/home/codespace/.local/lib/python3.12/site-packages/stack_data/utils.py\", line 145, in cached_property_wrapper\n",
      "    value = obj.__dict__[self.func.__name__] = self.func(obj)\n",
      "                                               ^^^^^^^^^^^^^^\n",
      "  File \"/home/codespace/.local/lib/python3.12/site-packages/stack_data/core.py\", line 614, in scope_pieces\n",
      "    scope_start, scope_end = self.source.line_range(self.scope)\n",
      "                             ^^^^^^^^^^^^^^^^^^^^^^^^^^^^^^^^^^\n",
      "  File \"/home/codespace/.local/lib/python3.12/site-packages/stack_data/core.py\", line 178, in line_range\n",
      "    return line_range(self.asttext(), node)\n",
      "                      ^^^^^^^^^^^^\n",
      "AttributeError: 'Source' object has no attribute 'asttext'\n"
     ]
    }
   ],
   "source": [
    "data.info()"
   ]
  },
  {
   "cell_type": "code",
   "execution_count": null,
   "metadata": {},
   "outputs": [],
   "source": []
  }
 ],
 "metadata": {
  "kernelspec": {
   "display_name": "Python 3",
   "language": "python",
   "name": "python3"
  },
  "language_info": {
   "codemirror_mode": {
    "name": "ipython",
    "version": 3
   },
   "file_extension": ".py",
   "mimetype": "text/x-python",
   "name": "python",
   "nbconvert_exporter": "python",
   "pygments_lexer": "ipython3",
   "version": "3.12.1"
  }
 },
 "nbformat": 4,
 "nbformat_minor": 2
}
